[2025-06-03T06:46:45.194+0000] {taskinstance.py:1159} INFO - Dependencies all met for dep_context=non-requeueable deps ti=<TaskInstance: prepare_churn_dataset.load scheduled__2025-06-03T00:00:00+00:00 [queued]>
[2025-06-03T06:46:45.205+0000] {taskinstance.py:1159} INFO - Dependencies all met for dep_context=requeueable deps ti=<TaskInstance: prepare_churn_dataset.load scheduled__2025-06-03T00:00:00+00:00 [queued]>
[2025-06-03T06:46:45.205+0000] {taskinstance.py:1361} INFO - Starting attempt 1 of 1
[2025-06-03T06:46:45.229+0000] {taskinstance.py:1382} INFO - Executing <Task(_PythonDecoratedOperator): load> on 2025-06-03 00:00:00+00:00
[2025-06-03T06:46:45.242+0000] {standard_task_runner.py:57} INFO - Started process 152 to run task
[2025-06-03T06:46:45.260+0000] {standard_task_runner.py:84} INFO - Running: ['***', 'tasks', 'run', 'prepare_churn_dataset', 'load', 'scheduled__2025-06-03T00:00:00+00:00', '--job-id', '11', '--raw', '--subdir', 'DAGS_FOLDER/churn.py', '--cfg-path', '/tmp/tmptq4gy8w7']
[2025-06-03T06:46:45.262+0000] {standard_task_runner.py:85} INFO - Job 11: Subtask load
[2025-06-03T06:46:45.357+0000] {task_command.py:416} INFO - Running <TaskInstance: prepare_churn_dataset.load scheduled__2025-06-03T00:00:00+00:00 [running]> on host 2ad5921a312f
[2025-06-03T06:46:45.533+0000] {taskinstance.py:1662} INFO - Exporting env vars: AIRFLOW_CTX_DAG_OWNER='***' AIRFLOW_CTX_DAG_ID='prepare_churn_dataset' AIRFLOW_CTX_TASK_ID='load' AIRFLOW_CTX_EXECUTION_DATE='2025-06-03T00:00:00+00:00' AIRFLOW_CTX_TRY_NUMBER='1' AIRFLOW_CTX_DAG_RUN_ID='scheduled__2025-06-03T00:00:00+00:00'
[2025-06-03T06:46:45.550+0000] {base.py:73} INFO - Using connection ID 'destination_db' for task execution.
[2025-06-03T06:46:45.561+0000] {taskinstance.py:1937} ERROR - Task failed with exception
Traceback (most recent call last):
  File "/home/airflow/.local/lib/python3.10/site-packages/airflow/decorators/base.py", line 221, in execute
    return_value = super().execute(context)
  File "/home/airflow/.local/lib/python3.10/site-packages/airflow/operators/python.py", line 192, in execute
    return_value = self.execute_callable()
  File "/home/airflow/.local/lib/python3.10/site-packages/airflow/operators/python.py", line 209, in execute_callable
    return self.python_callable(*self.op_args, **self.op_kwargs)
  File "/opt/airflow/dags/churn.py", line 86, in load
    hook.insert_rows(
  File "/home/airflow/.local/lib/python3.10/site-packages/airflow/providers/common/sql/hooks/sql.py", line 509, in insert_rows
    cur.execute(sql, values)
psycopg2.errors.UndefinedTable: relation "users_churn" does not exist
LINE 1: INSERT INTO users_churn (customer_id, begin_date, end_date, ...
                    ^

[2025-06-03T06:46:45.569+0000] {taskinstance.py:1400} INFO - Marking task as FAILED. dag_id=prepare_churn_dataset, task_id=load, execution_date=20250603T000000, start_date=20250603T064645, end_date=20250603T064645
[2025-06-03T06:46:45.596+0000] {standard_task_runner.py:104} ERROR - Failed to execute job 11 for task load (relation "users_churn" does not exist
LINE 1: INSERT INTO users_churn (customer_id, begin_date, end_date, ...
                    ^
; 152)
[2025-06-03T06:46:45.633+0000] {local_task_job_runner.py:228} INFO - Task exited with return code 1
[2025-06-03T06:46:45.649+0000] {taskinstance.py:2778} INFO - 0 downstream tasks scheduled from follow-on schedule check
